<?xml version="1.0" encoding="utf-8"?>
<!-- =================================================================================== -->
<!-- |    This document was autogenerated by xacro from mmrobot.urdf.xacro             | -->
<!-- |    EDITING THIS FILE BY HAND IS NOT RECOMMENDED                                 | -->
<!-- =================================================================================== -->
<robot name="mmrobot_description">
  <material name="Boxer_Black">
    <color rgba="0.1 0.1 0.1 1.0"/>
  </material>
  <material name="Boxer_Blue">
    <color rgba="0.0 0.0 0.8 1.0"/>
  </material>
  <material name="Boxer_Purple">
    <color rgba="0.6 0.0 0.6 1.0"/>
  </material>
  <material name="Boxer_Green">
    <color rgba="0.0 0.8 0.0 1.0"/>
  </material>
  <material name="Boxer_LimeGreen">
    <color rgba="0.3 0.8 0.3 1.0"/>
  </material>
  <material name="Boxer_Grey">
    <color rgba="0.5 0.5 0.5 1.0"/>
  </material>
  <material name="Boxer_DarkGrey">
    <color rgba="0.3 0.3 0.3 1.0"/>
  </material>
  <material name="Boxer_Red">
    <color rgba="0.8 0.0 0.0 1.0"/>
  </material>
  <material name="Boxer_Pink">
    <color rgba="0.8 0.4 0.8 1.0"/>
  </material>
  <material name="Boxer_White">
    <color rgba="1.0 1.0 1.0 1.0"/>
  </material>
  <material name="Boxer_Yellow">
    <color rgba="0.8 0.8 0.0 1.0"/>
  </material>
  <material name="Boxer_GreyTransparent">
    <color rgba="0.5 0.5 0.5 0.5"/>
  </material>
  <link name="chassis_link">
    <inertial>
      <origin rpy="1.5708 0 0" xyz="0 0 0.07"/>
      <mass value="51"/>
      <inertia ixx="2.3" ixy="0" ixz="0" iyy="3.35" iyz="0.00" izz="1.22"/>
    </inertial>
    <visual>
      <origin rpy="0 0 0" xyz="0 0 0"/>
      <geometry>
        <mesh filename="package://mobile_manipulator/boxer_description/meshes/chassis_link.dae"/>
      </geometry>
      <material name="">
        <color rgba="0.8 0.8 0.9 1"/>
      </material>
    </visual>
    <collision>
      <origin rpy="0 0 0" xyz="0 0 0"/>
      <geometry>
        <mesh filename="package://mobile_manipulator/boxer_description/meshes/chassis_link.STL"/>
      </geometry>
    </collision>
  </link>
  <link name="internal_link">
    <inertial>
      <origin rpy="0 0 0" xyz="0 0.19 -0.031"/>
      <mass value="31"/>
      <inertia ixx="1.19" ixy="0" ixz="0" iyy="1.82" iyz="0.0" izz="0.68"/>
    </inertial>
    <visual>
      <origin rpy="0 0 0" xyz="0 0 0"/>
      <geometry>
        <mesh filename="package://mobile_manipulator/boxer_description/meshes/internal_link.dae"/>
      </geometry>
      <material name="Boxer_DarkGrey"/>
    </visual>
    <collision>
      <origin rpy="0 0 0" xyz="0 0 0"/>
      <geometry>
        <!-- Mesh is scaled down slightly in length, to mitigate collision with laser rays due to slow physics updates  -->
        <!-- (The z axis is scaled since the whole model is rotated at the joint, and collision model resolution isn't
      very smart.) -->
        <mesh filename="package://mobile_manipulator/boxer_description/meshes/internal_link.STL"/>
      </geometry>
    </collision>
  </link>
  <joint name="internal_joint" type="fixed">
    <origin rpy="1.5708 0 0" xyz="0 0 0"/>
    <parent link="chassis_link"/>
    <child link="internal_link"/>
    <axis xyz="0 0 0"/>
  </joint>
  <link name="lift_link">
    <inertial>
      <origin rpy="0 0 0" xyz="0 0.076 0"/>
      <mass value="10"/>
      <inertia ixx="0.47" ixy="0" ixz="0" iyy="0.74" iyz="0" izz="0.29"/>
    </inertial>
    <visual>
      <origin rpy="0 0 0" xyz="0 0 0"/>
      <geometry>
        <mesh filename="package://mobile_manipulator/boxer_description/meshes/lift_link.dae"/>
      </geometry>
      <material name="">
        <color rgba="0.8 0.8 0.9 1"/>
      </material>
    </visual>
    <collision>
      <origin rpy="0 0 0" xyz="0 0 0"/>
      <geometry>
        <mesh filename="package://mobile_manipulator/boxer_description/meshes/lift_link.STL"/>
      </geometry>
    </collision>
  </link>
  <joint name="lift_joint" type="prismatic">
    <origin rpy="1.5708 0 0" xyz="0 0 0.177"/>
    <parent link="chassis_link"/>
    <child link="lift_link"/>
    <axis xyz="0 1 0"/>
    <limit effort="10000.0" lower="0" upper="0.078" velocity="0.02"/>
    <dynamics damping="100.0" friction="100"/>
  </joint>
  <link name="top_mount_bottom">
    <visual>
      <origin rpy="0 0 0" xyz="0 0 0"/>
      <geometry>
        <mesh filename="package://mobile_manipulator/boxer_description/meshes/top_plate.stl"/>
      </geometry>
      <material name="Boxer_DarkGrey"/>
    </visual>
    <collision>
      <origin rpy="0 0 0" xyz="0 0 0"/>
      <geometry>
        <mesh filename="package://mobile_manipulator/boxer_description/meshes/top_plate_collision.stl"/>
      </geometry>
    </collision>
  </link>
  <joint name="top_mount_bottom_joint" type="fixed">
    <origin rpy="0 -1.5707 -1.5707" xyz="0 0.1125 0"/>
    <parent link="lift_link"/>
    <child link="top_mount_bottom"/>
  </joint>
  <link name="extrusion1">
    <visual>
      <origin rpy="0 0 0" xyz="0 0 0"/>
      <geometry>
        <mesh filename="package://mobile_manipulator/boxer_description/meshes/extrusion.stl"/>
      </geometry>
      <material name="Boxer_DarkGrey"/>
    </visual>
    <collision>
      <origin rpy="0 0 0" xyz="0 0 0"/>
      <geometry>
        <mesh filename="package://mobile_manipulator/boxer_description/meshes/extrusion.stl"/>
      </geometry>
    </collision>
  </link>
  <joint name="extrusion1_joint" type="fixed">
    <origin rpy="0 0 0" xyz="-0.2785 0.1835 0"/>
    <parent link="top_mount_bottom"/>
    <child link="extrusion1"/>
  </joint>
  <link name="extrusion2">
    <visual>
      <origin rpy="0 0 0" xyz="0 0 0"/>
      <geometry>
        <mesh filename="package://mobile_manipulator/boxer_description/meshes/extrusion.stl"/>
      </geometry>
      <material name="Boxer_DarkGrey"/>
    </visual>
    <collision>
      <origin rpy="0 0 0" xyz="0 0 0"/>
      <geometry>
        <mesh filename="package://mobile_manipulator/boxer_description/meshes/extrusion.stl"/>
      </geometry>
    </collision>
  </link>
  <joint name="extrusion2_joint" type="fixed">
    <origin rpy="0 0 -1.5707" xyz="0.2785 0.1835 0"/>
    <parent link="top_mount_bottom"/>
    <child link="extrusion2"/>
  </joint>
  <link name="extrusion3">
    <visual>
      <origin rpy="0 0 0" xyz="0 0 0"/>
      <geometry>
        <mesh filename="package://mobile_manipulator/boxer_description/meshes/extrusion.stl"/>
      </geometry>
      <material name="Boxer_DarkGrey"/>
    </visual>
    <collision>
      <origin rpy="0 0 0" xyz="0 0 0"/>
      <geometry>
        <mesh filename="package://mobile_manipulator/boxer_description/meshes/extrusion.stl"/>
      </geometry>
    </collision>
  </link>
  <joint name="extrusion3_joint" type="fixed">
    <origin rpy="0 0 3.1414" xyz="0.2785 -0.1835 0"/>
    <parent link="top_mount_bottom"/>
    <child link="extrusion3"/>
  </joint>
  <link name="extrusion4">
    <visual>
      <origin rpy="0 0 0" xyz="0 0 0"/>
      <geometry>
        <mesh filename="package://mobile_manipulator/boxer_description/meshes/extrusion.stl"/>
      </geometry>
      <material name="Boxer_DarkGrey"/>
    </visual>
    <collision>
      <origin rpy="0 0 0" xyz="0 0 0"/>
      <geometry>
        <mesh filename="package://mobile_manipulator/boxer_description/meshes/extrusion.stl"/>
      </geometry>
    </collision>
  </link>
  <joint name="extrusion4_joint" type="fixed">
    <origin rpy="0 0 1.5707" xyz="-0.2785 -0.1835 0"/>
    <parent link="top_mount_bottom"/>
    <child link="extrusion4"/>
  </joint>
  <link name="top_mount">
    <visual>
      <origin rpy="0 0 0" xyz="0 0 0"/>
      <geometry>
        <mesh filename="package://mobile_manipulator/boxer_description/meshes/top_plate.stl"/>
      </geometry>
      <material name="Boxer_DarkGrey"/>
    </visual>
    <collision>
      <origin rpy="0 0 0" xyz="0 0 0"/>
      <geometry>
        <mesh filename="package://mobile_manipulator/boxer_description/meshes/top_plate_collision.stl"/>
      </geometry>
    </collision>
  </link>
  <!-- 0.27 in z direction because extrusion is 0.30, and plate is 0.1 -->
  <joint name="top_mount_joint" type="fixed">
    <origin rpy="0 0 0" xyz="0.2785 -0.1835 0.31"/>
    <parent link="extrusion1"/>
    <child link="top_mount"/>
  </joint>
  <link name="rotacastor_right_link">
    <inertial>
      <origin rpy="0 0 0" xyz="0 0 0"/>
      <mass value="100"/>
      <inertia ixx="0.2" ixy="0" ixz="0" iyy="0.2" iyz="0" izz="0.2"/>
    </inertial>
    <visual>
      <origin rpy="0 1.5708 0" xyz="0 0 0"/>
      <geometry>
        <cylinder length="0.06" radius="0.0625"/>
      </geometry>
      <material name="Boxer_Red"/>
    </visual>
    <collision>
      <origin rpy="0 1.5708 0" xyz="0 0 0"/>
      <geometry>
        <cylinder length="0.001" radius="0.0625"/>
      </geometry>
    </collision>
  </link>
  <joint name="rotacastor_right_joint" type="fixed">
    <origin rpy="0 0 0" xyz="-0.177 -0.274 0.043"/>
    <parent link="chassis_link"/>
    <child link="rotacastor_right_link"/>
    <axis xyz="1 0 0"/>
    <dynamics damping="1.0"/>
  </joint>
  <link name="rotacastor_left_link">
    <inertial>
      <origin rpy="0 0 0" xyz="0 0 0"/>
      <mass value="100"/>
      <inertia ixx="0.2" ixy="0" ixz="0" iyy="0.2" iyz="0" izz="0.2"/>
    </inertial>
    <visual>
      <origin rpy="0 1.5708 0" xyz="0 0 0"/>
      <geometry>
        <cylinder length="0.06" radius="0.0625"/>
      </geometry>
      <material name="Boxer_Red"/>
    </visual>
    <collision>
      <origin rpy="0 1.5708 0" xyz="0 0 0"/>
      <geometry>
        <cylinder length="0.001" radius="0.0625"/>
      </geometry>
    </collision>
  </link>
  <joint name="rotacastor_left_joint" type="fixed">
    <origin rpy="0 0 0" xyz="0.177 -0.274 0.043"/>
    <parent link="chassis_link"/>
    <child link="rotacastor_left_link"/>
    <axis xyz="1 0 0"/>
    <dynamics damping="1.0"/>
  </joint>
  <link name="wheel_right_link">
    <inertial>
      <origin rpy="0 0 0" xyz="0 0 0"/>
      <mass value="100"/>
      <inertia ixx="0.2" ixy="0" ixz="0" iyy="0.2" iyz="0" izz="0.2"/>
    </inertial>
    <visual>
      <origin rpy="0 1.5708 0" xyz="0 0 0"/>
      <geometry>
        <cylinder length="0.05" radius="0.080"/>
      </geometry>
      <material name="Boxer_Red"/>
    </visual>
    <collision>
      <origin rpy="0 1.5708 0" xyz="0 0 0"/>
      <geometry>
        <cylinder length="0.001" radius="0.080"/>
      </geometry>
    </collision>
  </link>
  <joint name="wheel_right_joint" type="continuous">
    <origin rpy="0 0 0" xyz="-0.247 0.157 0.058"/>
    <parent link="chassis_link"/>
    <child link="wheel_right_link"/>
    <axis xyz="1 0 0"/>
    <limit effort="10000" velocity="1000"/>
    <dynamics damping="1.0"/>
  </joint>
  <link name="wheel_left_link">
    <inertial>
      <origin rpy="0 0 0" xyz="0 0 0"/>
      <mass value="100"/>
      <inertia ixx="0.2" ixy="0" ixz="0" iyy="0.2" iyz="0" izz="0.2"/>
    </inertial>
    <visual>
      <origin rpy="0 1.5708 0" xyz="0 0 0"/>
      <geometry>
        <cylinder length="0.05" radius="0.080"/>
      </geometry>
      <material name="Boxer_Red"/>
    </visual>
    <collision>
      <origin rpy="0 1.5708 0" xyz="0 0 0"/>
      <geometry>
        <cylinder length="0.001" radius="0.080"/>
      </geometry>
    </collision>
  </link>
  <joint name="wheel_left_joint" type="continuous">
    <origin rpy="0 0 0" xyz="0.247 0.157 0.058"/>
    <parent link="chassis_link"/>
    <child link="wheel_left_link"/>
    <axis xyz="1 0 0"/>
    <limit effort="10000" velocity="1000"/>
    <dynamics damping="1.0"/>
  </joint>
  <!-- Base link with no geometry or inertia, because KDL needs it
to be that way. -->
  <link name="base_link"/>
  <joint name="base_chassis_joint" type="fixed">
    <origin rpy="0 0 1.5708" xyz="0.15 0 0"/>
    <parent link="base_link"/>
    <child link="chassis_link"/>
  </joint>
  <!-- Projection of base_link on the ground to get the 3D data
in the right frame w.r.t the ground. -->
  <link name="base_footprint"/>
  <joint name="base_footprint_joint" type="fixed">
    <origin rpy="0 0 0" xyz="0 0 -0.08"/>
    <parent link="base_link"/>
    <child link="base_footprint"/>
  </joint>
  <!-- Link for the position of the laser. -->
  <link name="front_laser"/>
  <joint name="base_laser_joint" type="fixed">
    <!-- LIDAR is moved forward slightly, from 0.407, to mitigate collision with internal_link due to slow physics updates  -->
    <origin rpy="3.14159 0 0" xyz="0.44 0 0.172"/>
    <parent link="base_link"/>
    <child link="front_laser"/>
  </joint>
  <!-- Stereo camera link to base_link. -->
  <link name="stereo"/>
  <joint name="stereo_camera_joint" type="fixed">
    <origin rpy="3.14159 0 0" xyz="0.4884 0 0.05465"/>
    <parent link="base_link"/>
    <child link="stereo"/>
  </joint>
  <link name="stereo_left"/>
  <joint name="stereo_left_joint" type="fixed">
    <origin rpy="-1.570796327 0 -1.570796327" xyz="0 0.060 0"/>
    <parent link="stereo"/>
    <child link="stereo_left"/>
  </joint>
  <link name="stereo_right"/>
  <joint name="stereo_right_joint" type="fixed">
    <origin rpy="-1.570796327 0 -1.570796327" xyz="0 -0.060 0"/>
    <parent link="stereo"/>
    <child link="stereo_right"/>
  </joint>
  <!-- Sonar links to base link joints -->
  <link name="rear_left_sonar_link"/>
  <joint name="rear_left_sonar_joint" type="fixed">
    <origin rpy="0 0 3.14159" xyz="-0.2043 0.150 0.157"/>
    <parent link="base_link"/>
    <child link="rear_left_sonar_link"/>
  </joint>
  <link name="rear_right_sonar_link"/>
  <joint name="rear_right_sonar_joint" type="fixed">
    <origin rpy="0 0 3.141597" xyz="-0.2043 -0.150 0.157"/>
    <parent link="base_link"/>
    <child link="rear_right_sonar_link"/>
  </joint>
  <transmission name="wheel_left_transmission">
    <type>transmission_interface/SimpleTransmission</type>
    <joint name="wheel_left_joint">
      <hardwareInterface>hardware_interface/VelocityJointInterface</hardwareInterface>
    </joint>
    <actuator name="wheel_left_actuator">
      <mechanicalReduction>1</mechanicalReduction>
    </actuator>
  </transmission>
  <transmission name="wheel_right_transmission">
    <type>transmission_interface/SimpleTransmission</type>
    <joint name="wheel_right_joint">
      <hardwareInterface>hardware_interface/VelocityJointInterface</hardwareInterface>
    </joint>
    <actuator name="wheel_right_actuator">
      <mechanicalReduction>1</mechanicalReduction>
    </actuator>
  </transmission>
  <transmission name="lift_transmission">
    <type>transmission_interface/SimpleTransmission</type>
    <joint name="lift_joint">
      <hardwareInterface>hardware_interface/PositionJointInterface</hardwareInterface>
    </joint>
    <actuator name="lift_actuator">
      <mechanicalReduction>1</mechanicalReduction>
    </actuator>
  </transmission>
  <link name="imu_link"/>
  <joint name="imu_joint" type="fixed">
    <parent link="base_link"/>
    <child link="imu_link"/>
    <origin rpy="0 0 -0.78539816339744828" xyz="0.191959 -0.086412 0.18455965360"/>
  </joint>
  <!-- Simulation for BOXER's IMU. -->
  <!--
    <gazebo reference="imu_link">
      <gravity>true</gravity>
      <sensor name="imu_sensor" type="imu">
        <always_on>true</always_on>
        <update_rate>100</update_rate>
        <visualize>true</visualize>
        <topic>__default_topic__</topic>
        <plugin filename="libgazebo_ros_imu_sensor.so" name="imu_plugin">
          <topicName>imu</topicName>
          <bodyName>imu_link</bodyName>
          <updateRateHZ>10.0</updateRateHZ>
          <gaussianNoise>0.0</gaussianNoise>
          <xyzOffset>0 0 0</xyzOffset>
          <rpyOffset>0 0 0</rpyOffset>
          <frameName>imu_link</frameName>
        </plugin>
        <pose>0 0 0 0 0 0</pose>
      </sensor>
    </gazebo>
-->
  <gazebo>
    <plugin filename="libhector_gazebo_ros_imu.so" name="imu_controller">
      <robotNamespace>/mmrobot</robotNamespace>
      <updateRate>50.0</updateRate>
      <bodyName>imu_link</bodyName>
      <frameId>base_link</frameId>
      <topicName>imu/data</topicName>
      <accelDrift>0.005 0.005 0.005</accelDrift>
      <accelGaussianNoise>0.005 0.005 0.005</accelGaussianNoise>
      <rateDrift>0.005 0.005 0.005 </rateDrift>
      <rateGaussianNoise>0.005 0.005 0.005 </rateGaussianNoise>
      <headingDrift>0.005</headingDrift>
      <headingGaussianNoise>0.005</headingGaussianNoise>
    </plugin>
  </gazebo>
  <gazebo>
    <!-- Plugin for ros_control (actuate drive motors, lift). -->
    <!--
      <plugin name="gazebo_ros_control" filename="libgazebo_ros_control.so">
        <robotNamespace>/${robot_namespace}</robotNamespace>
      </plugin>
      <plugin name="boxer_controller" filename="libgazebo_ros_diff_drive.so">
        <commandTopic>cmd_vel</commandTopic>
        <odometryTopic>odom</odometryTopic>
        <odometryFrame>odom</odometryFrame>
        <odometrySource>world</odometrySource>
        <publishOdomTF>true</publishOdomTF>
        <robotBaseFrame>base_link</robotBaseFrame>
        <publishWheelTF>false</publishWheelTF>
        <publishTf>true</publishTf>
        <publishWheelJointState>true</publishWheelJointState>
        <legacyMode>false</legacyMode>
        <updateRate>30</updateRate>
        <leftJoint>wheel_left_joint</leftJoint>
        <rightJoint>wheel_right_joint</rightJoint>
        <wheelSeparation>0.160</wheelSeparation>
        <wheelDiameter>0.066</wheelDiameter>
        <wheelAcceleration>1</wheelAcceleration>
        <wheelTorque>10</wheelTorque>
        <rosDebugLevel>na</rosDebugLevel>
      </plugin>
-->
    <!-- Groud Truth Position, Pose, and Rates plugin -->
    <plugin filename="libgazebo_ros_p3d.so" name="gazebo_ros_p3d">
      <robotNamespace>/mmrobot</robotNamespace>
      <bodyName>base_link</bodyName>
      <topicName>ground_truth_odom</topicName>
      <alwaysOn>true</alwaysOn>
      <updateRate>100.0</updateRate>
    </plugin>
    <!-- BOXER Platform Plugin -->
    <!--     <plugin name="boxer_platform_plugin" filename="libboxer_gazebo_plugins.so">
        <robotNamespace>/${robot_namespace}</robotNamespace>
      </plugin> -->
  </gazebo>
  <gazebo reference="front_laser">
    <sensor name="front_laser_link" type="ray">
      <pose>0 0 0 0 0 0</pose>
      <visualize>false</visualize>
      <update_rate>16</update_rate>
      <ray>
        <scan>
          <horizontal>
            <samples>720</samples>
            <resolution>1</resolution>
            <min_angle>-2.35619</min_angle>
            <max_angle>2.35619</max_angle>
          </horizontal>
        </scan>
        <range>
          <min>0.10</min>
          <max>30.0</max>
          <resolution>0.01</resolution>
        </range>
        <noise>
          <type>gaussian</type>
          <mean>0.0</mean>
          <stddev>0.001</stddev>
        </noise>
      </ray>
      <plugin filename="libgazebo_ros_laser.so" name="gazebo_ros_laser">
        <robotNamespace>/</robotNamespace>
        <topicName>front/scan</topicName>
        <frameName>front_laser</frameName>
      </plugin>
    </sensor>
  </gazebo>
  <gazebo reference="rear_left_sonar_link">
    <sensor name="rear_left_sonar" type="ray">
      <always_on>true</always_on>
      <update_rate>5</update_rate>
      <pose>0 0 0 0 0 0</pose>
      <visualize>false</visualize>
      <ray>
        <scan>
          <horizontal>
            <samples>5</samples>
            <resolution>1</resolution>
            <min_angle>-0.13083332777</min_angle>
            <max_angle>0.13083332777</max_angle>
          </horizontal>
          <vertical>
            <samples>5</samples>
            <resolution>1</resolution>
            <min_angle>-0.13083332777</min_angle>
            <max_angle>0.13083332777</max_angle>
          </vertical>
        </scan>
        <range>
          <min>0.1</min>
          <max>1.2</max>
          <resolution>0.01</resolution>
        </range>
      </ray>
      <plugin filename="libhector_gazebo_ros_sonar.so" name="gazebo_ros_rear_left_sonar_controller">
        <robotNamespace>/mmrobot</robotNamespace>
        <gaussianNoise>0.005</gaussianNoise>
        <topicName>/sonar/left</topicName>
        <frameId>rear_left_sonar_link</frameId>
        <updateRate>5</updateRate>
      </plugin>
    </sensor>
  </gazebo>
  <gazebo reference="rear_right_sonar_link">
    <sensor name="rear_right_sonar" type="ray">
      <always_on>false</always_on>
      <update_rate>5</update_rate>
      <pose>0 0 0 0 0 0</pose>
      <visualize>false</visualize>
      <ray>
        <scan>
          <horizontal>
            <samples>5</samples>
            <resolution>1</resolution>
            <min_angle>-0.13083332777</min_angle>
            <max_angle>0.13083332777</max_angle>
          </horizontal>
          <vertical>
            <samples>5</samples>
            <resolution>1</resolution>
            <min_angle>-0.13083332777</min_angle>
            <max_angle>0.13083332777</max_angle>
          </vertical>
        </scan>
        <range>
          <min>0.1</min>
          <max>1.2</max>
          <resolution>0.01</resolution>
        </range>
      </ray>
      <plugin filename="libhector_gazebo_ros_sonar.so" name="gazebo_ros_rear_right_sonar_controller">
        <robotNamespace>/mmrobot</robotNamespace>
        <gaussianNoise>0.005</gaussianNoise>
        <topicName>/sonar/right</topicName>
        <frameId>rear_right_sonar_link</frameId>
        <updateRate>5</updateRate>
      </plugin>
    </sensor>
  </gazebo>
  <gazebo reference="stereo_left">
    <material>Gazebo/Grey</material>
    <sensor name="camera_left" type="camera">
      <update_rate>10</update_rate>
      <camera name="camera_left">
        <pose>0 0 0 0 -1.5707 1.5707</pose>
        <horizontal_fov>1.0471975512</horizontal_fov>
        <image>
          <width>1288</width>
          <height>964</height>
          <format>BAYER_BGGR8</format>
        </image>
        <clip>
          <near>0.5</near>
          <far>300</far>
        </clip>
        <noise>
          <type>gaussian</type>
          <mean>0.0</mean>
          <stddev>0.007</stddev>
        </noise>
      </camera>
      <plugin filename="libgazebo_ros_camera.so" name="camera_controller">
        <alwaysOn>true</alwaysOn>
        <updateRate>10</updateRate>
        <cameraName>camera_left</cameraName>
        <imageTopicName>image_raw</imageTopicName>
        <cameraInfoTopicName>camera_info</cameraInfoTopicName>
        <frameName>stereo_left</frameName>
        <hackBaseline>0.07</hackBaseline>
        <distortionK1>0.0</distortionK1>
        <distortionK2>0.0</distortionK2>
        <distortionK3>0.0</distortionK3>
        <distortionT1>0.0</distortionT1>
        <distortionT2>0.0</distortionT2>
      </plugin>
    </sensor>
  </gazebo>
  <!-- Right -->
  <!--gazebo reference="stereo_right">
      <material>Gazebo/Grey</material>
      <sensor type="camera" name="camera_right">
        <update_rate>10</update_rate>
        <camera name="camera_right">
          <pose>0 0 0 0 -1.5707 1.5707</pose>
          <horizontal_fov>1.0471975512</horizontal_fov>
          <image>
            <width>1288</width>
            <height>964</height>
            <format>BAYER_BGGR8</format>
          </image>
          <clip>
            <near>0.5</near>
            <far>300</far>
          </clip>
          <noise>
            <type>gaussian</type>
            <mean>0.0</mean>
            <stddev>0.007</stddev>
          </noise>
        </camera>

        <plugin name="camera_controller" filename="libgazebo_ros_camera.so">
          <alwaysOn>true</alwaysOn>
          <updateRate>10</updateRate>
          <cameraName>camera_right</cameraName>
          <imageTopicName>image_raw</imageTopicName>
          <cameraInfoTopicName>camera_info</cameraInfoTopicName>
          <frameName>stereo_right</frameName>
          <hackBaseline>0.07</hackBaseline>
          <distortionK1>0.0</distortionK1>
          <distortionK2>0.0</distortionK2>
          <distortionK3>0.0</distortionK3>
          <distortionT1>0.0</distortionT1>
          <distortionT2>0.0</distortionT2>
        </plugin>
      </sensor>
    </gazebo-->
  <gazebo reference="rotacastor_left_link">
    <!-- For castors, we need high PID values to avoid slippage -->
    <kp>100000000.0</kp>
    <kd>10000.0</kd>
    <!-- Castors will slide freely to allow turning -->
    <mu1>0</mu1>
    <mu2>0</mu2>
    <minDepth>0.0</minDepth>
    <material>Gazebo/DarkGrey</material>
    <selfCollide>false</selfCollide>
  </gazebo>
  <gazebo reference="rotacastor_right_link">
    <!-- For castors, we need high PID values to avoid slippage -->
    <kp>100000000.0</kp>
    <kd>10000.0</kd>
    <!-- Castors will slide freely to allow turning -->
    <mu1>0</mu1>
    <mu2>0</mu2>
    <minDepth>0.0</minDepth>
    <material>Gazebo/DarkGrey</material>
    <selfCollide>false</selfCollide>
  </gazebo>
  <gazebo reference="wheel_left_link">
    <!-- For wheels, we need high PID values to avoid slippage -->
    <kp>100000000.0</kp>
    <kd>10000.0</kd>
    <!-- Wheels have friction to prevent slippage -->
    <mu1>100.0</mu1>
    <mu2>100.0</mu2>
    <minDepth>0.0</minDepth>
    <material>Gazebo/DarkGrey</material>
    <selfCollide>false</selfCollide>
  </gazebo>
  <gazebo reference="wheel_right_link">
    <!-- For wheels, we need high PID values to avoid slippage -->
    <kp>100000000.0</kp>
    <kd>10000.0</kd>
    <!-- Wheels have friction to prevent slippage -->
    <mu1>100.0</mu1>
    <mu2>100.0</mu2>
    <minDepth>0.0</minDepth>
    <material>Gazebo/DarkGrey</material>
    <selfCollide>false</selfCollide>
  </gazebo>
  <!-- Lift surface treatments. -->
  <gazebo reference="lift_link">
    <kp>100</kp>
    <kd>100</kd>
    <mu1>100</mu1>
    <mu2>100</mu2>
    <minDepth>0.0</minDepth>
  </gazebo>
  <!-- Panda Arm -->
  <joint name="mmrobot_joint_top_mount" type="fixed">
    <parent link="top_mount"/>
    <child link="mmrobot_link0"/>
    <origin rpy="0 0 0" xyz="-0.15 0 0"/>
  </joint>
  <!-- end for simulation -->
  <link name="mmrobot_link0">
    <visual>
      <geometry>
        <mesh filename="package://mobile_manipulator/franka_description/meshes/visual/link0.dae"/>
      </geometry>
    </visual>
    <collision>
      <geometry>
        <mesh filename="package://mobile_manipulator/franka_description/meshes/collision/link0.stl"/>
      </geometry>
    </collision>
    <!-- for simulation -->
    <inertial>
      <origin rpy="0 0 0" xyz="0 0 0"/>
      <mass value="3.06"/>
      <inertia ixx="0.3" ixy="0.0" ixz="0.0" iyy="0.3" iyz="0.0" izz="0.3"/>
    </inertial>
    <!-- end for simulation -->
  </link>
  <link name="mmrobot_link1">
    <visual>
      <geometry>
        <mesh filename="package://mobile_manipulator/franka_description/meshes/visual/link1.dae"/>
      </geometry>
    </visual>
    <collision>
      <geometry>
        <mesh filename="package://mobile_manipulator/franka_description/meshes/collision/link1.stl"/>
      </geometry>
    </collision>
    <!-- for simulation -->
    <inertial>
      <origin rpy="0 0 0" xyz="0 0 0"/>
      <mass value="2.34"/>
      <inertia ixx="0.3" ixy="0.0" ixz="0.0" iyy="0.3" iyz="0.0" izz="0.3"/>
    </inertial>
    <!-- end for simulation -->
  </link>
  <joint name="mmrobot_joint1" type="revolute">
    <safety_controller k_position="100.0" k_velocity="40.0" soft_lower_limit="-2.8973" soft_upper_limit="2.8973"/>
    <origin rpy="0 0 0" xyz="0 0 0.333"/>
    <parent link="mmrobot_link0"/>
    <child link="mmrobot_link1"/>
    <axis xyz="0 0 1"/>
    <limit effort="87" lower="-2.8973" upper="2.8973" velocity="2.1750"/>
    <!-- for simulation -->
    <dynamics damping="1.0"/>
    <!-- end for simulation -->
  </joint>
  <link name="mmrobot_link2">
    <visual>
      <geometry>
        <mesh filename="package://mobile_manipulator/franka_description/meshes/visual/link2.dae"/>
      </geometry>
    </visual>
    <collision>
      <geometry>
        <mesh filename="package://mobile_manipulator/franka_description/meshes/collision/link2.stl"/>
      </geometry>
    </collision>
    <!-- for simulation -->
    <inertial>
      <origin rpy="0 0 0" xyz="0 0 0"/>
      <mass value="2.36"/>
      <inertia ixx="0.3" ixy="0.0" ixz="0.0" iyy="0.3" iyz="0.0" izz="0.3"/>
    </inertial>
    <!-- end for simulation -->
  </link>
  <joint name="mmrobot_joint2" type="revolute">
    <safety_controller k_position="100.0" k_velocity="40.0" soft_lower_limit="-1.7628" soft_upper_limit="1.7628"/>
    <origin rpy="-1.57079632679 0 0" xyz="0 0 0"/>
    <parent link="mmrobot_link1"/>
    <child link="mmrobot_link2"/>
    <axis xyz="0 0 1"/>
    <limit effort="87" lower="-1.7628" upper="1.7628" velocity="2.1750"/>
    <!-- for simulation -->
    <dynamics damping="1.0"/>
    <!-- end for simulation -->
  </joint>
  <link name="mmrobot_link3">
    <visual>
      <geometry>
        <mesh filename="package://mobile_manipulator/franka_description/meshes/visual/link3.dae"/>
      </geometry>
    </visual>
    <collision>
      <geometry>
        <mesh filename="package://mobile_manipulator/franka_description/meshes/collision/link3.stl"/>
      </geometry>
    </collision>
    <!-- for simulation -->
    <inertial>
      <origin rpy="0 0 0" xyz="0 0 0"/>
      <mass value="2.38"/>
      <inertia ixx="0.3" ixy="0.0" ixz="0.0" iyy="0.3" iyz="0.0" izz="0.3"/>
    </inertial>
    <!-- end for simulation -->
  </link>
  <joint name="mmrobot_joint3" type="revolute">
    <safety_controller k_position="100.0" k_velocity="40.0" soft_lower_limit="-2.8973" soft_upper_limit="2.8973"/>
    <origin rpy="1.57079632679 0 0" xyz="0 -0.316 0"/>
    <parent link="mmrobot_link2"/>
    <child link="mmrobot_link3"/>
    <axis xyz="0 0 1"/>
    <limit effort="87" lower="-2.8973" upper="2.8973" velocity="2.1750"/>
    <!-- for simulation -->
    <dynamics damping="1.0"/>
    <!-- end for simulation -->
  </joint>
  <link name="mmrobot_link4">
    <visual>
      <geometry>
        <mesh filename="package://mobile_manipulator/franka_description/meshes/visual/link4.dae"/>
      </geometry>
    </visual>
    <collision>
      <geometry>
        <mesh filename="package://mobile_manipulator/franka_description/meshes/collision/link4.stl"/>
      </geometry>
    </collision>
    <!-- for simulation -->
    <inertial>
      <origin rpy="0 0 0" xyz="0 0 0"/>
      <mass value="2.43"/>
      <inertia ixx="0.3" ixy="0.0" ixz="0.0" iyy="0.3" iyz="0.0" izz="0.3"/>
    </inertial>
    <!-- end for simulation -->
  </link>
  <joint name="mmrobot_joint4" type="revolute">
    <safety_controller k_position="100.0" k_velocity="40.0" soft_lower_limit="-3.0718" soft_upper_limit="-0.0698"/>
    <origin rpy="1.57079632679 0 0" xyz="0.0825 0 0"/>
    <parent link="mmrobot_link3"/>
    <child link="mmrobot_link4"/>
    <axis xyz="0 0 1"/>
    <limit effort="87" lower="-3.0718" upper="-0.0698" velocity="2.1750"/>
    <!-- for simulation -->
    <dynamics damping="1.0"/>
    <!-- end for simulation -->
  </joint>
  <link name="mmrobot_link5">
    <visual>
      <geometry>
        <mesh filename="package://mobile_manipulator/franka_description/meshes/visual/link5.dae"/>
      </geometry>
    </visual>
    <collision>
      <geometry>
        <mesh filename="package://mobile_manipulator/franka_description/meshes/collision/link5.stl"/>
      </geometry>
    </collision>
    <!-- for simulation -->
    <inertial>
      <origin rpy="0 0 0" xyz="0 0 0"/>
      <mass value="3.5"/>
      <inertia ixx="0.3" ixy="0.0" ixz="0.0" iyy="0.3" iyz="0.0" izz="0.3"/>
    </inertial>
    <!-- end for simulation -->
  </link>
  <joint name="mmrobot_joint5" type="revolute">
    <safety_controller k_position="100.0" k_velocity="40.0" soft_lower_limit="-2.8973" soft_upper_limit="2.8973"/>
    <origin rpy="-1.57079632679 0 0" xyz="-0.0825 0.384 0"/>
    <parent link="mmrobot_link4"/>
    <child link="mmrobot_link5"/>
    <axis xyz="0 0 1"/>
    <limit effort="12" lower="-2.8973" upper="2.8973" velocity="2.6100"/>
    <!-- for simulation -->
    <dynamics damping="1.0"/>
    <!-- end for simulation -->
  </joint>
  <link name="mmrobot_link6">
    <visual>
      <geometry>
        <mesh filename="package://mobile_manipulator/franka_description/meshes/visual/link6.dae"/>
      </geometry>
    </visual>
    <collision>
      <geometry>
        <mesh filename="package://mobile_manipulator/franka_description/meshes/collision/link6.stl"/>
      </geometry>
    </collision>
    <!-- for simulation -->
    <inertial>
      <origin rpy="0 0 0" xyz="0 0 0"/>
      <mass value="1.47"/>
      <inertia ixx="0.3" ixy="0.0" ixz="0.0" iyy="0.3" iyz="0.0" izz="0.3"/>
    </inertial>
    <!-- end for simulation -->
  </link>
  <joint name="mmrobot_joint6" type="revolute">
    <safety_controller k_position="100.0" k_velocity="40.0" soft_lower_limit="-0.0175" soft_upper_limit="3.7525"/>
    <origin rpy="1.57079632679 0 0" xyz="0 0 0"/>
    <parent link="mmrobot_link5"/>
    <child link="mmrobot_link6"/>
    <axis xyz="0 0 1"/>
    <limit effort="12" lower="-0.0175" upper="3.7525" velocity="2.6100"/>
    <!-- for simulation -->
    <dynamics damping="1.0"/>
    <!-- end for simulation -->
  </joint>
  <link name="mmrobot_link7">
    <visual>
      <geometry>
        <mesh filename="package://mobile_manipulator/franka_description/meshes/visual/link7.dae"/>
      </geometry>
    </visual>
    <collision>
      <geometry>
        <mesh filename="package://mobile_manipulator/franka_description/meshes/collision/link7.stl"/>
      </geometry>
    </collision>
    <!-- for simulation -->
    <inertial>
      <origin rpy="0 0 0" xyz="0 0 0"/>
      <mass value="0.45"/>
      <inertia ixx="0.3" ixy="0.0" ixz="0.0" iyy="0.3" iyz="0.0" izz="0.3"/>
    </inertial>
    <!-- end for simulation -->
  </link>
  <joint name="mmrobot_joint7" type="revolute">
    <safety_controller k_position="100.0" k_velocity="40.0" soft_lower_limit="-2.8973" soft_upper_limit="2.8973"/>
    <origin rpy="1.57079632679 0 0" xyz="0.088 0 0"/>
    <parent link="mmrobot_link6"/>
    <child link="mmrobot_link7"/>
    <axis xyz="0 0 1"/>
    <limit effort="12" lower="-2.8973" upper="2.8973" velocity="2.6100"/>
    <!-- for simulation -->
    <dynamics damping="1.0"/>
    <!-- end for simulation -->
  </joint>
  <link name="mmrobot_link8">
    <!-- for simulation -->
    <inertial>
      <origin rpy="0 0 0" xyz="0 0 0"/>
      <mass value="0.0"/>
      <inertia ixx="0.3" ixy="0.0" ixz="0.0" iyy="0.3" iyz="0.0" izz="0.3"/>
    </inertial>
    <!-- end for simulation -->
  </link>
  <joint name="mmrobot_joint8" type="fixed">
    <origin rpy="0 0 0" xyz="0 0 0.107"/>
    <parent link="mmrobot_link7"/>
    <child link="mmrobot_link8"/>
    <axis xyz="0 0 0"/>
  </joint>
  <joint name="mmrobot_hand_joint" type="fixed">
    <parent link="mmrobot_link8"/>
    <child link="mmrobot_hand"/>
    <origin rpy="0 0 -0.785398163397" xyz="0 0 0"/>
  </joint>
  <link name="mmrobot_hand">
    <visual>
      <geometry>
        <mesh filename="package://mobile_manipulator/franka_description/meshes/visual/hand.dae"/>
      </geometry>
    </visual>
    <collision>
      <geometry>
        <mesh filename="package://mobile_manipulator/franka_description/meshes/collision/hand.stl"/>
      </geometry>
    </collision>
    <!-- for simulation -->
    <inertial>
      <origin rpy="0 0 0" xyz="0 0 0"/>
      <mass value="0.68"/>
      <inertia ixx="0.1" ixy="0.0" ixz="0.0" iyy="0.1" iyz="0.0" izz="0.1"/>
    </inertial>
    <!-- end for simulation -->
  </link>
  <link name="mmrobot_leftfinger">
    <visual>
      <geometry>
        <mesh filename="package://mobile_manipulator/franka_description/meshes/visual/finger.dae"/>
      </geometry>
    </visual>
    <collision>
      <geometry>
        <mesh filename="package://mobile_manipulator/franka_description/meshes/collision/finger.stl"/>
      </geometry>
    </collision>
    <!-- for simulation -->
    <inertial>
      <origin rpy="0 0 0" xyz="0 0 0"/>
      <mass value="0.01"/>
      <inertia ixx="0.1" ixy="0.0" ixz="0.0" iyy="0.1" iyz="0.0" izz="0.1"/>
    </inertial>
    <!-- end for simulation -->
  </link>
  <link name="mmrobot_rightfinger">
    <visual>
      <origin rpy="0 0 3.14159265359" xyz="0 0 0"/>
      <geometry>
        <mesh filename="package://mobile_manipulator/franka_description/meshes/visual/finger.dae"/>
      </geometry>
    </visual>
    <collision>
      <origin rpy="0 0 3.14159265359" xyz="0 0 0"/>
      <geometry>
        <mesh filename="package://mobile_manipulator/franka_description/meshes/collision/finger.stl"/>
      </geometry>
    </collision>
    <!-- for simulation -->
    <inertial>
      <origin rpy="0 0 0" xyz="0 0 0"/>
      <mass value="0.01"/>
      <inertia ixx="0.1" ixy="0.0" ixz="0.0" iyy="0.1" iyz="0.0" izz="0.1"/>
    </inertial>
    <!-- end for simulation -->
  </link>
  <joint name="mmrobot_finger_joint1" type="prismatic">
    <parent link="mmrobot_hand"/>
    <child link="mmrobot_leftfinger"/>
    <origin rpy="0 0 0" xyz="0 0 0.0584"/>
    <axis xyz="0 1 0"/>
    <limit effort="20" lower="0.0" upper="0.04" velocity="0.2"/>
  </joint>
  <joint name="mmrobot_finger_joint2" type="prismatic">
    <parent link="mmrobot_hand"/>
    <child link="mmrobot_rightfinger"/>
    <origin rpy="0 0 0" xyz="0 0 0.0584"/>
    <axis xyz="0 -1 0"/>
    <limit effort="20" lower="0.0" upper="0.04" velocity="0.2"/>
  </joint>
  <!-- Link0 -->
  <gazebo reference="mmrobot_link0">
    <material>Gazebo/Grey</material>
    <mu1>0.2</mu1>
    <mu2>0.2</mu2>
  </gazebo>
  <!-- Link1 -->
  <gazebo reference="mmrobot_link1">
    <material>Gazebo/White</material>
    <mu1>0.2</mu1>
    <mu2>0.2</mu2>
  </gazebo>
  <!-- Link2 -->
  <gazebo reference="mmrobot_link2">
    <material>Gazebo/White</material>
    <mu1>0.2</mu1>
    <mu2>0.2</mu2>
  </gazebo>
  <!-- Link3 -->
  <gazebo reference="mmrobot_link3">
    <material>Gazebo/White</material>
    <mu1>0.2</mu1>
    <mu2>0.2</mu2>
  </gazebo>
  <!-- Link4 -->
  <gazebo reference="mmrobot_link4">
    <material>Gazebo/White</material>
    <mu1>0.2</mu1>
    <mu2>0.2</mu2>
  </gazebo>
  <!-- Link5 -->
  <gazebo reference="mmrobot_link5">
    <material>Gazebo/White</material>
    <mu1>0.2</mu1>
    <mu2>0.2</mu2>
  </gazebo>
  <!-- Link6 -->
  <gazebo reference="mmrobot_link6">
    <material>Gazebo/White</material>
    <mu1>0.2</mu1>
    <mu2>0.2</mu2>
  </gazebo>
  <!-- Link7 -->
  <gazebo reference="mmrobot_link7">
    <material>Gazebo/Grey</material>
    <mu1>0.2</mu1>
    <mu2>0.2</mu2>
  </gazebo>
  <!-- Link8 -->
  <gazebo reference="mmrobot_link8">
    <material>Gazebo/Grey</material>
    <mu1>0.2</mu1>
    <mu2>0.2</mu2>
  </gazebo>
  <!-- LinkHand -->
  <gazebo reference="mmrobot_hand">
    <material>Gazebo/Grey</material>
    <mu1>0.2</mu1>
    <mu2>0.2</mu2>
  </gazebo>
  <!-- LinkRightFinger -->
  <gazebo reference="mmrobot_rightfinger">
    <material>Gazebo/Grey</material>
    <mu1>0.2</mu1>
    <mu2>0.2</mu2>
  </gazebo>
  <!-- LinkLeftFinger -->
  <gazebo reference="mmrobot_leftfinger">
    <material>Gazebo/Grey</material>
    <mu1>0.2</mu1>
    <mu2>0.2</mu2>
  </gazebo>
  <!-- Load Gazebo lib and set the robot namespace -->
  <gazebo>
    <plugin filename="libgazebo_ros_control.so" name="gazebo_ros_control">
      <robotNamespace>/mmrobot</robotNamespace>
    </plugin>
  </gazebo>
  <transmission name="mmrobot_tran_1">
    <type>transmission_interface/SimpleTransmission</type>
    <joint name="mmrobot_joint1">
      <hardwareInterface>hardware_interface/EffortJointInterface</hardwareInterface>
    </joint>
    <actuator name="mmrobot_motor_1">
      <hardwareInterface>hardware_interface/EffortJointInterface</hardwareInterface>
      <mechanicalReduction>1</mechanicalReduction>
    </actuator>
  </transmission>
  <transmission name="mmrobot_tran_2">
    <type>transmission_interface/SimpleTransmission</type>
    <joint name="mmrobot_joint2">
      <hardwareInterface>hardware_interface/EffortJointInterface</hardwareInterface>
    </joint>
    <actuator name="mmrobot_motor_2">
      <hardwareInterface>hardware_interface/EffortJointInterface</hardwareInterface>
      <mechanicalReduction>1</mechanicalReduction>
    </actuator>
  </transmission>
  <transmission name="mmrobot_tran_3">
    <type>transmission_interface/SimpleTransmission</type>
    <joint name="mmrobot_joint3">
      <hardwareInterface>hardware_interface/EffortJointInterface</hardwareInterface>
    </joint>
    <actuator name="mmrobot_motor_3">
      <hardwareInterface>hardware_interface/EffortJointInterface</hardwareInterface>
      <mechanicalReduction>1</mechanicalReduction>
    </actuator>
  </transmission>
  <transmission name="mmrobot_tran_4">
    <type>transmission_interface/SimpleTransmission</type>
    <joint name="mmrobot_joint4">
      <hardwareInterface>hardware_interface/EffortJointInterface</hardwareInterface>
    </joint>
    <actuator name="mmrobot_motor_4">
      <hardwareInterface>hardware_interface/EffortJointInterface</hardwareInterface>
      <mechanicalReduction>1</mechanicalReduction>
    </actuator>
  </transmission>
  <transmission name="mmrobot_tran_5">
    <type>transmission_interface/SimpleTransmission</type>
    <joint name="mmrobot_joint5">
      <hardwareInterface>hardware_interface/EffortJointInterface</hardwareInterface>
    </joint>
    <actuator name="mmrobot_motor_5">
      <hardwareInterface>hardware_interface/EffortJointInterface</hardwareInterface>
      <mechanicalReduction>1</mechanicalReduction>
    </actuator>
  </transmission>
  <transmission name="mmrobot_tran_6">
    <type>transmission_interface/SimpleTransmission</type>
    <joint name="mmrobot_joint6">
      <hardwareInterface>hardware_interface/EffortJointInterface</hardwareInterface>
    </joint>
    <actuator name="mmrobot_motor_6">
      <hardwareInterface>hardware_interface/EffortJointInterface</hardwareInterface>
      <mechanicalReduction>1</mechanicalReduction>
    </actuator>
  </transmission>
  <transmission name="mmrobot_tran_7">
    <type>transmission_interface/SimpleTransmission</type>
    <joint name="mmrobot_joint7">
      <hardwareInterface>hardware_interface/EffortJointInterface</hardwareInterface>
    </joint>
    <actuator name="mmrobot_motor_7">
      <hardwareInterface>hardware_interface/EffortJointInterface</hardwareInterface>
      <mechanicalReduction>1</mechanicalReduction>
    </actuator>
  </transmission>
  <transmission name="mmrobot_leftfinger">
    <type>transmission_interface/SimpleTransmission</type>
    <joint name="mmrobot_finger_joint1">
      <hardwareInterface>hardware_interface/EffortJointInterface</hardwareInterface>
    </joint>
    <actuator name="mmrobot_finger_joint1">
      <hardwareInterface>hardware_interface/EffortJointInterface</hardwareInterface>
      <mechanicalReduction>1</mechanicalReduction>
    </actuator>
  </transmission>
  <transmission name="mmrobot_rightfinger">
    <type>transmission_interface/SimpleTransmission</type>
    <joint name="mmrobot_finger_joint2">
      <hardwareInterface>hardware_interface/EffortJointInterface</hardwareInterface>
    </joint>
    <actuator name="mmrobot_finger_joint2">
      <hardwareInterface>hardware_interface/EffortJointInterface</hardwareInterface>
      <mechanicalReduction>1</mechanicalReduction>
    </actuator>
  </transmission>
</robot>

